Workbook

Sheet Superset Topik-Tokoh
A1: No | B1: Item | C1: Jenis (Topik/Tokoh) | D1: Konteks Singkat | E1: Tag AI | F1: Kelompok Kanonik
A2: 1 | B2: David Hilbert | C2: Tokoh | D2: Pengusul PR#10, semboyan kein ignorabimus, Hilbert's Program, pidato radio 1930 | E2: CL | F2: David Hilbert
A3: 2 | B3: Emil du Bois-Reymond | C3: Tokoh | D3: Sumber klaim 'ignoramus et ignorabimus' yang dibantah semboyan Hilbert | E3: CL | F3: Emil du Bois-Reymond
A4: 3 | B4: Diophantus | C4: Tokoh | D4: Asal nama 'persamaan Diophantine', abad ke-3 M | E4: CL | F4: Diophantus
A5: 4 | B5: Wilhelm Ackermann | C5: Tokoh | D5: Ko-perumus Entscheidungsproblem bersama Hilbert, 1928 | E5: CL | F5: Wilhelm Ackermann
A6: 5 | B6: Kurt Gödel | C6: Tokoh | D6: Teorema ketidaklengkapan 1931; fungsi rekursif | E6: CL | F6: Kurt Gödel
A7: 6 | B7: Alonzo Church | C7: Tokoh | D7: Kalkulus lambda 1936; Entscheidungsproblem tak terpecahkan | E7: CL | F7: Alonzo Church
A8: 7 | B8: Alan Turing | C8: Tokoh | D8: Mesin Turing 1936; Entscheidungsproblem tak terpecahkan | E8: CL | F8: Alan Turing
A9: 8 | B9: Julia Robinson | C9: Tokoh | D9: Hipotesis J.R.; Teorema DPR 1961; batas 9 variabel | E9: CL | F9: Julia Robinson
A10: 9 | B10: Martin Davis | C10: Tokoh | D10: Teorema Davis-Putnam-Robinson 1961 | E10: CL | F10: Martin Davis
A11: 10 | B11: Hilary Putnam | C11: Tokoh | D11: Teorema Davis-Putnam-Robinson 1961 | E11: CL | F11: Hilary Putnam
A12: 11 | B12: Yuri Matiyasevich | C12: Tokoh | D12: Penutup celah via Fibonacci 1970; Teorema MRDP; batas 9 variabel | E12: CL | F12: Yuri Matiyasevich
A13: 12 | B13: Jan Denef | C13: Tokoh | D13: Gagasan kurva eliptik pengganti Pell; HTP cincin bilangan bulat 1978 | E13: CL | F13: Jan Denef
... A739: 738 | B739: Grup Selmer | C739: Topik | D739: Alat teknis geometri aritmetika modern | E739: QW | F739: Grup/Teori Selmer & Descent (kurva eliptik)

Sheet Konsistensi Prep vs Draft
A1: No | B1: Tag AI | C1: Status (Match/Prep only/Draft only) | D1: Item | E1: Catatan/Lokasi
A2: 1 | B2: CL | C2: Match | D2: David Hilbert | E2: Latar Belakang & Tabel; MVC Bab 1,3,17
A3: 2 | B3: CL | C3: Prep only | D3: Emil du Bois-Reymond | E3: Latar Belakang §1 saja; tidak muncul lagi di MVC/Daftar Pustaka
A4: 3 | B4: CL | C4: Match | D4: Diophantus | E4: Tabel baris 4; MVC Bab 2 'Warisan Diophantus'
A5: 4 | B5: CL | C5: Prep only | D5: Wilhelm Ackermann | E5: Tabel baris 6 saja; MVC Bab 6 sebut Entscheidungsproblem tanpa nama Ackermann
A6: 5 | B6: CL | C6: Match | D6: Kurt Gödel | E6: Tabel baris 7,9; MVC Bab 5,6,17,18; Daftar Pustaka A
A7: 6 | B7: CL | C7: Match | D7: Alonzo Church | E7: Tabel baris 10; MVC Bab 5,6; Daftar Pustaka A
A8: 7 | B8: CL | C8: Match | D8: Alan Turing | E8: Tabel baris 11; MVC Bab 5,6; Daftar Pustaka A
A9: 8 | B9: CL | C9: Match | D9: Julia Robinson | E9: Tabel baris 12,13,15,17; MVC Bab 7,8,19
A10: 9 | B10: CL | C10: Match | D10: Martin Davis | E10: Tabel baris 13,15; MVC Bab 8,19; Daftar Pustaka A
A11: 10 | B11: CL | C11: Match | D11: Hilary Putnam | E11: Tabel baris 13,15; MVC Bab 8,19; Daftar Pustaka A
A12: 11 | B12: CL | C12: Match | D12: Yuri Matiyasevich | E12: Tabel baris 14,15,17; MVC Bab 9,19; Daftar Pustaka A
A13: 12 | B13: CL | C13: Match | D13: Jan Denef | E13: Tabel baris 18,19; MVC Bab 12,13; Daftar Pustaka B
... A739: 738 | B739: QW | C739: Draft only | D739: Grup Selmer | E739: MVC Bab 13 saja

Sheet Ringkasan per AI
A1: Tag AI | B1: Model | C1: Jml Topik | D1: Jml Tokoh | E1: Match Rate (%) | F1: Catatan
A2: GR | B2: Grok | C2: 21 | D2: 25 | E2: 89.7 | F2: Draft ringkas & padat, gaya bullet points per Bab (bukan naratif seperti CL). 4 item Prep only (Emil du Bois-Reymond, Diophantus sbg nama literal, klaim 'ignorabimus', Teorema Ketidaklengkapan Gödel disebut namanya hanya di Tabel -- MVC Bab 4 cuma sebut 'karya Gödel (1931)'). 7 item Draft only: 4 nama baru murni dari Bab 9 (Denef, Lipshitz, Mazur, Rubin -- hasil parsial 1980an-2010an yg tak masuk Tabel), 2 dari Daftar Pustaka (Poonen, Howlett), 1 topik (makalah ekspositori Koymans-Pagano 2026). Temuan kualitas: baris Tabel 3B utk 'H10 atas Q' punya teks yg tampak rusak/typo ('Alexandra terbuka (masih aktif diteliti, m.l. Alexandra Shlapentokh dkk.)') -- kemungkinan kata 'masih' tertukar jadi 'Alexandra' di awal frasa. TEMUAN Tahap 1.5 (dicek ulang via QC, sumber primer): 'Leonard Lipshitz' -- ejaan yg dipakai GR ('Lipshitz') SUDAH BENAR (dikonfirmasi halaman fakultas Purdue resmi + volume AMS yg sama persis); kesimpulan awal Tahap 1.5 yg menuduh ini salah eja adalah KELIRU, sudah dibalik. 'J. Howlett' (Daftar Pustaka) TERVERIFIKASI AKURAT scr penuh: byline asli artikel 'New Proofs Probe the Limits of Mathematical Truth' (quantamagazine.org, 3 Feb 2025) memang Joseph Howlett -- venue Quanta Magazine yg disebut GR BENAR. Sebaliknya, sitasi 'Wolchover' di draft CL utk artikel yg SAMA ternyata KELIRU: dicek langsung ke arsip tulisan Wolchover di Quanta, ia tak pernah menulis ttg HTP (area liputannya fisika/Qualia). Jadi ini SATU artikel, byline yg benar Howlett; GR akurat, CL salah atribusi jurnalis. KOREKSI KECIL tambahan (dicek ulang via QC): entri 'Eisenträger' sempat salah tertulis nama depan 'Katrina', seharusnya 'Kirsten' (Penn State) -- sudah diperbaiki.
A3: CL | B3: Claude | C3: 30 | D3: 33 | E3: 91.7 | F3: Draft sangat komprehensif (MVC 20 bab + Daftar Pustaka 4 kategori). 5 item Prep only (Emil du Bois-Reymond, Wilhelm Ackermann, Hilbert's Program, pidato 'Mathematische Probleme' secara literal, klaim 'ignoramus et ignorabimus' du Bois-Reymond) -- rencana Prep tak sepenuhnya dieksekusi verbatim ke MVC. 3 item Draft only (Tesis Church-Turing, Van Geel, Wolchover). Temuan kualitas: ejaan Lipschitz/Lipshitz tidak konsisten -- KOREKSI Tahap 1.5 (dicek ulang via QC): ejaan benar justru 'Lipshitz' (sumber primer: halaman fakultas Purdue), bukan 'Lipschitz' spt kesimpulan awal. TEMUAN Tahap 1.5 tambahan (dicek ulang via QC): entri 'Wolchover' di Daftar Pustaka adl GALAT FAKTUAL CL -- artikel yg dikutip byline aslinya Joseph Howlett, bukan Wolchover (dicek langsung ke arsip Quanta).
A4: PE | B4: Perplexity | C4: 23 | D4: 24 | E4: 88.4 | F4: Draft dgn MATCH RATE TERTINGGI sejauh ini (~85%): 20/24 baris Tabel tereksekusi konsisten hingga MVC (26 sub-bab format 1.1-4.7) & Daftar Pustaka. Ciri unik: Latar Belakang & Tabel penuh sitasi URL inline (plato.stanford, arxiv, quantamagazine, dll.) -- gaya 'search-grounded' berbeda dari semua AI lain. Bibliografinya SANGAT ringan tokoh baru: nyaris SEMUA nama di Daftar Pustaka sudah ada di Tabel (hanya 'Mathematische Probleme' sbg item baru, itu pun cuma judul, bukan tokoh baru) -- banyak sumbernya institusional/ensiklopedia (Wikipedia, Stanford Encyclopedia, Encyclopedia of Mathematics, TheoremDB) drpd buku individual spt draft KI/TE. 4 item Prep only murni krn MVC parafrase konsep dgn istilah berbeda (bukan krn topiknya dihilangkan): 'teori komputabilitas' (MVC pakai 'teori komputasi modern'), 'fungsi rekursif' (MVC fokus 'fungsi eksponensial'), 'batas formalisme' (MVC bahas tema sama scr implisit), dan Ackermann/Koenigsmann (nama disebut di Tabel tp tak diulang). TEMUAN KUALITAS (TERVERIFIKASI Tahap 1.5): draft scr konsisten menulis inisial 'C. Ho' (bukan 'W. Ho'/Wei Ho) utk anggota tim Alpöge-Bhargava-Ho-Shnidman, di Tabel MAUPUN Daftar Pustaka -- dikonfirmasi via web search ini GALAT FAKTUAL PE (nama benar Wei Ho), bukan sekadar dugaan typo. VERIFIKASI: ditemukan & diperbaiki 1 false negative -- term 'pasangan universal' gagal cocok krn notasi '(ν, δ)' disisipi di tengah frasa ('pasangan (ν, δ) universal'); setelah term diperbaiki, item ini terbukti Match bukan Prep only.
A5: QW | B5: Qwen | C5: 13 | D5: 29 | E5: 82.8 | F5: AI KE-12/TERAKHIR dlm siklus PR#10. Draft bergaya 'panduan penulis' dgn banyak meta-komentar ('Mari kita susun...', 'Catatan untuk Lapisan...') dan tabel ringkasan per-Lapisan yg merekap Bab/Tokoh/Output -- format unik drpd 11 AI lain. Update tabel 3B-nya AKURAT scr faktual (mirip ME, GR, KI): menangkap Koymans-Pagano 2024 & Alpöge dgn benar, meski dgn detail lebih sedikit drpd draft ME/KI/TE (tak menyebut Bhargava/Ho/Shnidman/Eisenträger/Poonen sbg tim kedua scr eksplisit -- hanya 'Lev Alpöge' disebut sbg 'dukungan karya'). 3 Tokoh Prep only (Rivest, Shamir, Adleman utk RSA) -- topik kriptografi disinggung lg di Bab 14 tp tanpa nama RSA/penemunya scr eksplisit. 11 Tokoh Draft only: beberapa organik dari narasi (Fermat, Brouwer, Herbrand, Post, Mazur, Poonen di Bab 4/5/11), sisanya murni Daftar Pustaka 'pelengkap suasana' (Reid, Penrose, Yandell, Singh, Hoffman -- termasuk Paul Erdős yg cuma disebut sbg subjek biografi Hoffman, bukan kontributor PR#10). VERIFIKASI: ditemukan & diperbaiki 1 false positive besar -- term pendek 'rsa' ternyata cocok sbg substring kata Indonesia 'peRSAmaan' yg muncul 29x di seluruh Draft; setelah term diganti jadi nama lengkap (Rivest/Shamir/Adleman), terbukti ketiganya Prep only, bukan Match -- pengingat penting bhw substring pendek (2-3 huruf) sangat rawan false positive dlm teks Indonesia.
A6: TE | B6: Tera AI | C6: 35 | D6: 46 | E6: 69.4 | F6: Draft besar: MVC 21 bab (4 lapisan x 5 bab + Gerbang), Daftar Pustaka 25 sumber dikelompokkan per lapisan + kategori 'Sumber Pendamping' (gaya/suasana) -- format mirip KI. TEMUAN PALING PENTING (butuh perhatian khusus di Tahap 1.5 & narasi Tahap 3): Tabel 3B memuat riset terkini 2024-2026 yg sangat kaya (Koymans-Pagano, finitely generated rings, formal verifikasi Coq, Hipotesis Mazur, kasus R/C via Tarski-Seidenberg) TAPI tak satu pun dari 21 bab MVC yg benar2 membahasnya scr eksplisit -- diverifikasi ganda via grep, 0 kemunculan utk 'Koymans', 'Pagano', 'Coq', 'Mazur', 'Tarski', 'Seidenberg', 'finitely generated' di seluruh Draft. Bab 11-15 (harusnya 'Frontier') malah fokus ke topik lain: polinomial universal 1976, hierarki kompleksitas, kriptografi kurva eliptik generik, ekstensi Q/p-adic generik, filsafat. ARTINYA: riset Prep (Tabel) tentang terobosan paling mutakhir TIDAK tereksekusi ke MVC -- pola 'Prep kaya, Draft tak menindaklanjuti' yg jauh lebih ekstrem drpd AI lain manapun sejauh ini. Sebaliknya, 20 Tokoh Draft only (16 di antaranya murni dari Daftar Pustaka 'Sumber Pendamping'/filosofis: Hofstadter, Gessen, Alexander, Zammito, Nagel, Newman, Franzén, Hersh, dll.) menunjukkan MVC-nya justru memperkaya diri dgn rujukan filosofis/naratif yg sama sekali tak direncanakan di Tabel.
A7: CO | B7: Copilot | C7: 20 | D7: 19 | E7: 75 | F7: Draft paling RINGKAS sejauh ini: MVC hanya 17 bab, Daftar Pustaka 10 entri -- semuanya tokoh yg sudah ada di Tabel, TIDAK ADA tokoh baru murni dari Daftar Pustaka (beda dari semua AI sebelumnya). Tabel 3B merevisi baris 'Persamaan Diofantin medan lain' dgn menambah nama (Denef, Koenigsmann) menggantikan placeholder 'komunitas teori bilangan modern', TAPI juga MENGHAPUS baris 'Filsafat matematika' dari 3A tanpa keterangan -- dicatat tetap sbg Prep only krn sempat muncul di 3A. 5 item Prep only Tokoh (Euler, Turing -- keduanya disebut di Tabel tp MVC-nya parafrase tanpa nama; Bhargava, Shnidman -- disebut di Tabel baris 'Elliptic curves' tp tak pernah muncul lagi; Kai -- lihat catatan di bawah). 3 item Draft only (Persamaan Pell, Fermat Kecil, Fermat's Last Theorem -- detail tradisi teori bilangan yg baru muncul di Bab 3 MVC). TEMUAN Tahap 1.5 (sudah diverifikasi via web search, KEDUANYA TERBUKTI AKURAT, bukan halusinasi spt dugaan awal): (1) 'Jonathan Brossard' (2026) & klaimnya ttg bukti konstruktif PR#10 via Rocq/Coq terkait Rice's theorem -- paper riil arXiv:2604.16477, terbit April 2026 (setelah cutoff pengetahuan Claude, karena itu awalnya tak terverifikasi dari memori). Deskripsi CO cocok persis dgn abstrak aslinya. (2) 'Kai (2026)' sbg kontributor Green-Tao sieve extension MUNCUL JUGA di draft KI dgn klaim serupa -- keduanya merujuk Wataru Kai (Tohoku University), hasilnya (arXiv:2306.16983) memang dikutip di paper Koymans-Pagano & ABHS. Konvergensi 2 AI independen pada figur yg sama ternyata krn keduanya akurat, bukan kebetulan halusinasi yg sama. (3) TEMUAN TAMBAHAN Tahap 1.5 (dicek ulang via QC): Daftar Pustaka entri 8 mencantumkan 'arXiv:2503.xxxxx' -- placeholder literal yg belum diisi CO sendiri, bukan disamarkan sengaja. Judul yg dikutip jg ternyata cocok dgn paper EKSPOSITORI Koymans-Pagano Feb 2026 (arXiv:2602.04468), bukan paper hasil asli Des 2024 (arXiv:2412.01768) -- draft CO mencampur judul & tahun dari 2 paper Koymans-Pagano yg berbeda.
A8: LE | B8: Le Chat | C8: 18 | D8: 61 | E8: 81 | F8: TEMUAN PALING PENTING: draft ini SAMA SEKALI tidak menyebut terobosan riil HTP 2020an (Koymans, Pagano, Alpoge, Bhargava, Ho, Shnidman, finitely generated rings dll. -- NIHIL, 0 kemunculan). Saat diminta 'update sampai 2026', draft malah menambah topik SEKITAR PR#10 yg tak nyambung langsung ke riset HTP: komputasi kuantum (Shor, Grover), kriptografi post-kuantum (NIST), AI/ML terkini (Hinton, LeCun, Ng), verifikasi program otomatis, blockchain (Buterin, Wood) -- Lapisan III 'FRONTIER' (Bab 10-15) jadi berisi scope creep ke tren komputer populer drpd riset matematis PR#10 aktual. 36 Tokoh Draft only (JUMLAH TERBANYAK dari semua AI sejauh ini) HAMPIR SEMUA murni dari Daftar Pustaka yg melebar jauh ke buku populer/textbook umum (AI ethics -- Floridi, Bostrom; quantum computing -- Nielsen-Chuang, Aaronson; general CS -- Knuth, Sipser; bahkan whitepaper Bitcoin/Ethereum) -- pola bibliography paling tangensial dari PR#10 di antara semua AI. TEMUAN KUALITAS PALING MENCURIGAKAN: entri Daftar Pustaka 'Rao, A. (2018). The Limits of Mathematics... AMS' -- judul ini sangat mirip buku KLASIK Gregory Chaitin 'The Limits of Mathematics' (Springer, bukan AMS) -- kemungkinan besar sitasi keliru/halusinasi yg menggabungkan judul asli dgn penulis & penerbit yg salah. VERIFIKASI: ditemukan & diperbaiki 1 false positive -- term 'Ng,' utk 'Andrew Ng' ternyata cocok kata Indonesia biasa ('yang,') bukan nama; setelah dikoreksi, Andrew Ng terbukti Prep only bukan Match.
A9: DE | B9: DeepSeek | C9: 25 | D9: 30 | E9: 71.1 | F9: Draft bercorak akademis/kepustakaan (22 entri Daftar Pustaka, 4 kategori sumber). 8 item Prep only (Diophantus, Euler, Gauss, Ackermann, van den Dries, Levin, Karp, Friedman, Paulson, Cohen, +Problem Hilbert #1/#2/#6) -- tabel 3A/3B memuat banyak tokoh pendukung yang tak ditindaklanjuti eksplisit di MVC/Daftar Pustaka. 7 item Draft only (Tesis Church-Turing, Halting Problem, Bentuk normal Davis, Eliminasi Putnam, Hipotesis Julia Robinson bernama eksplisit, Barisan Fibonacci, Aksioma Peano) -- rincian teknis MVC Bab 3,5,6,7 yang tak muncul di Tabel. 3 Tokoh Draft only murni dari Daftar Pustaka (Enderton, Soare, Harrison). Tabel 3A memakai label topik tematik luas (mis. 'Logika Matematika & Sistem Formal') alih-alih topik spesifik seperti draft CL.
A10: KI | B10: Kimi | C10: 50 | D10: 66 | E10: 68.5 | F10: Draft JAUH terbesar dari semua AI sejauh ini: MVC 40 bab (bukan 12-20), tabel 36 baris, Daftar Pustaka 39 sumber dlm 8 kategori. 29 item Prep only -- proporsi besar krn tabel memuat banyak tokoh 'pendukung tematik' (Thue, Siegel, Cook, Levin, Lenstra, Wittgenstein, Grothendieck, Roth, Hardy, Littlewood, Chomsky, dll.) yg tak pernah ditindaklanjuti di MVC/Daftar Pustaka. 24 item Draft only, 15 di antaranya Tokoh MURNI dari Daftar Pustaka (Hofstadter, Penrose, Ruelle, Byers, Singh, Derbyshire, du Sautoy, Browder, Yandell, Reid, Petzold, dll.) -- draft ini jauh lebih bibliography-heavy drpd AI lain, banyak sumber hanya tangensial ke PR#10 (buku filsafat/populer). TEMUAN Tahap 1.5 (sudah diverifikasi via web search): (1) 'Kai (peneliti)' TERVERIFIKASI AKURAT -- nama lengkap Wataru Kai (Tohoku University), hasil Green-Tao utk number fields (arXiv:2306.16983) memang dikutip di kedua paper HTP 2024-2025. BUKAN halusinasi seperti dugaan awal. (2) Entri Daftar Pustaka Alpoge-Bhargava-Ho-Shnidman (2025) eksplisit berlabel arXiv:2501.00000 '(placeholder, sesuaikan dengan publikasi aktual)' -- draft SENDIRI mengakui ini nomor arXiv palsu/estimasi, bukan sitasi riil. (3) Ejaan 'Matiyasevich' vs 'Matijasevic' tidak konsisten (Daftar Pustaka B, entri Davis-Matijasevic-Robinson 1976). (4) Tabel punya sejumlah baris Topik yg tumpang tindih scr konsep tp diberi label berbeda demi memberi setiap tokoh barisnya sendiri (mis. 'Logika Matematika' [Davis] vs 'Teori Himpunan & Logika' [Putnam] -- secara substansi topik yg sama). (5) Ditemukan & dikoreksi 1 false positive verifikasi terprogram: term 'Post' di Draft semua berasal dari 'post-quantum/post-kuantum', bukan nama Emil Post -- setelah dikoreksi manual, Emil Post = Prep only (bukan Match). (6) TEMUAN TAMBAHAN Tahap 1.5 (dicek ulang via QC, dikonfirmasi via fetch langsung ke arXiv): nomor arXiv utk Koymans-Pagano di Daftar Pustaka (2401.05904) SALAH -- itu paper fisika nuklir tak terkait; nomor yg benar 2412.01768. Ini bukan placeholder yg disengaja, tapi nomor valid yg kebetulan mengarah ke paper lain -- kesalahan sitasi konkret, bukan sekadar 'CEK'.
A11: GE | B11: Gemini | C11: 15 | D11: 18 | E11: 79.2 | F11: Draft sedang (12 bab MVC, Daftar Pustaka dikelompokkan per Lapisan -- format unik, AI lain pakai daftar flat). Tabel 3B TIDAK merevisi/reprint tabel 3A, hanya menambah 3 baris baru -- beda dari CL/DE/KI yg reprint penuh. 6 item Draft only Tokoh SEMUANYA dari Daftar Pustaka (Heath, Shnidman, Alpoge, Bhargava, Ho, Chaitin) -- khususnya menarik: Shnidman/Alpoge/Bhargava/Ho (tim ABHS 2025) TIDAK disebut namanya di Tabel (row 10 cuma bilang 'tim peneliti independen lain'), beda dari draft CL/GR/KI yg menampilkan mereka menonjol di Tabel. 1 Tokoh & 3 Topik Prep only (Church/Lambda Calculus disebut di Tabel tp tak pernah muncul lagi; Hipotesis J.R./Fibonacci & 'recursively enumerable' disebut di Tabel tp MVC Bab 6 cuma parafrase umum). Menarik: 'Mathematische Probleme' (judul asli pidato Hilbert) di sini DRAFT ONLY (muncul di Daftar Pustaka, bukan di Latar Belakang) -- kebalikan dari draft CL yg Prep only utk item yg sama. 3 Topik Draft only baru: Formalisme matematika, judul asli pidato, dan bab ttg PR#10 & batas Artificial Intelligence (Bab 11) -- sudut pandang unik yg tak muncul di AI lain.
A12: ME | B12: Meta AI | C12: 20 | D12: 43 | E12: 94.7 | F12: MATCH RATE TERTINGGI dari SEMUA 11 AI sejauh ini (54/63 = 86%): SEMUA 37 Tokoh dari Tabel (3A+3B) tereksekusi konsisten sampai ke MVC (12 bab, 4 Lapisan) & Daftar Pustaka -- termasuk nama-nama teknis 'terdalam' spt Eisenträger, Dittmann, Daans, Skolem, Zhi-Wei Sun yg di AI lain sering jadi Prep only. Tabel 3B-nya paling AKURAT scr faktual di antara semua AI: menangkap persis rangkaian riset HTP 2020an yg benar (Denef-Lipschitz-Shapiro-Shlapentokh-Pheidas -> Mazur-Poonen-Koenigsmann-Park -> Eisenträger dkk -> Koymans-Pagano & Alpöge-Bhargava-Ho-Shnidman 2024-2025) -- kontras tajam dgn draft LE yg sama sekali tak menyentuh riset ini. 3 item Prep only HANYA soal label tabel yg tak diulang literal (bukan soal substansi hilang) -- 'Ketidaklengkapan Aritmetika', 'Alat Representasi Bilangan', 'Contoh Motivasi Klasik' semuanya konsepnya tetap ada di MVC, cuma nama kolom Topik-nya tak dikutip verbatim. 6 Tokoh Draft only wajar & bernilai tambah: Emil Post (mengomentari PR#10 1944), Nikolai Vorob'ev (sumber ide Fibonacci Matiyasevich), Paul Cohen (analogi PR#1), dan 3 nama dari Daftar Pustaka (Hersh, Murty, Fodden). Tidak ditemukan temuan kualitas data yg mencurigakan (tak ada klaim aneh/tak terverifikasi spt 'Kai' di draft KI/CO atau 'Rao, A.' di draft LE) -- draft paling 'bersih' & konsisten sejauh ini. KOREKSI KECIL Tahap 1.5 (dicek ulang via QC): entri 'Eisenträger' sempat salah tertulis nama depan 'Katrina', seharusnya 'Kirsten' (Penn State) -- sudah diperbaiki; tak mengubah penilaian draft ini tetap paling bersih.
A13: GP | B13: GPT | C13: 38 | D13: 36 | E13: 50.7 | F13: Draft SANGAT BERBEDA gaya dari 8 AI lain: bergaya 'proses berpikir keras' bukan output final -- Tabel 3A+3B mencapai 58 baris (termasuk banyak baris dgn daftar 'dll.' berisi nama tangensial: Hermite/Lindemann/Gelfond/Schneider utk kontras PR#7, Lang/Serre, Lenstra/Pomerance/Cohen, Vojta/Bombieri). Section C unik: AI ini pertama menulis PETA 37-slot penuh (Lapisan I=6, II=9, III=10, IV=12 bab, masing2 dgn tabel cakupan topik), LALU secara eksplisit mengkritik diri sendiri ('kalau tujuan kita benar2 MVC, saya malah akan memangkasnya cukup brutal') dan mengusulkan versi final 15 bab + Gerbang. Kedua versi (37-slot & 15-bab) dihitung sbg Draft krn sama2 di bawah '# C. MVC'. HASIL PALING MENONJOL: rasio Match/Prep-only nyaris 50:50 (37 Match, 36 Prep only) -- JAUH lebih rendah drpd AI lain manapun. ini krn 21 dari 22 Tokoh Prep-only adalah nama dlm daftar 'dll.' tabel 3B yg TAK PERNAH disebut lagi scr individual di 37 maupun 15 bab MVC manapun -- tabelnya riset sangat luas tapi chapter-nya sengaja tetap ramping mengikuti core cast (Hilbert-Godel-Church-Turing-Davis-Putnam-Robinson-Matiyasevich-Faltings-Poonen-Shlapentokh). Draft only HANYA 1 item (editor B. Jack Copeland dari Daftar Pustaka) -- draft ini nyaris tak memperkenalkan hal baru di Section C, konsisten dgn komentar eksplisit penulis bahwa 'detail nanti tinggal diisi ke slot yg sudah dibuat'. Daftar Pustaka sendiri juga di-trim eksplisit oleh AI dari 14 sumber jadi '7 Core Bibliography' berbintang -- pola self-editing berlapis yg tak ditemukan di AI manapun sejauh ini.

Sheet Legend Tag AI
A1: Model | B1: Tag
A2: Grok | B2: GR
A3: Claude | B3: CL
A4: Perplexity | B4: PE
A5: Qwen | B5: QW
A6: Tera AI | B6: TE
A7: Copilot | B7: CO
A8: Le Chat | B8: LE
A9: DeepSeek | B9: DE
A10: Kimi | B10: KI
A11: Gemini | B11: GE
A12: Meta AI | B12: ME
A13: GPT | B13: GP

Sheet Konsensus 12 AI
A1: No | B1: Kelompok Kanonik | C1: Jenis | D1: Jumlah AI | E1: Daftar AI | F1: Konsensus | G1: Kategori
A2: 1 | B2: Alan Turing | C2: Tokoh | D2: 12 | E2: GR, CL, PE, QW, TE, CO, LE, DE, KI, GE, ME, GP | F2: 12/12 | G2: Universal (11-12/12)
A3: 2 | B3: David Hilbert | C3: Tokoh | D3: 12 | E3: GR, CL, PE, QW, TE, CO, LE, DE, KI, GE, ME, GP | F3: 12/12 | G3: Universal (11-12/12)
A4: 3 | B4: Diophantus | C4: Tokoh | D4: 12 | E4: GR, CL, PE, QW, TE, CO, LE, DE, KI, GE, ME, GP | F4: 12/12 | G4: Universal (11-12/12)
A5: 4 | B5: Hilary Putnam | C5: Tokoh | D5: 12 | E5: GR, CL, PE, QW, TE, CO, LE, DE, KI, GE, ME, GP | F5: 12/12 | G5: Universal (11-12/12)
A6: 5 | B6: Julia Robinson | C6: Tokoh | D6: 12 | E6: GR, CL, PE, QW, TE, CO, LE, DE, KI, GE, ME, GP | F6: 12/12 | G6: Universal (11-12/12)
A7: 6 | B7: Martin Davis | C7: Tokoh | D7: 12 | E7: GR, CL, PE, QW, TE, CO, LE, DE, KI, GE, ME, GP | F7: 12/12 | G7: Universal (11-12/12)
A8: 7 | B8: Yuri Matiyasevich | C8: Tokoh | D8: 12 | E8: GR, CL, PE, QW, TE, CO, LE, DE, KI, GE, ME, GP | F8: 12/12 | G8: Universal (11-12/12)
A9: 8 | B9: Alonzo Church | C9: Tokoh | D9: 11 | E9: GR, CL, PE, QW, TE, LE, DE, KI, GE, ME, GP | F9: 11/12 | G9: Universal (11-12/12)
A10: 9 | B10: Kurt Gödel | C10: Tokoh | D10: 11 | E10: GR, CL, PE, QW, TE, LE, DE, KI, GE, ME, GP | F10: 11/12 | G10: Universal (11-12/12)
A11: 10 | B11: Bjorn Poonen | C11: Tokoh | D11: 9 | E11: GR, CL, QW, TE, CO, DE, GE, ME, GP | F11: 9/12 | G11: Mayoritas (7-10/12)
A12: 11 | B12: Carlo Pagano | C12: Tokoh | D12: 9 | E12: GR, CL, PE, QW, TE, CO, KI, GE, ME | F12: 9/12 | G12: Mayoritas (7-10/12)
A13: 12 | B13: Peter Koymans | C13: Tokoh | D13: 9 | E13: GR, CL, PE, QW, TE, CO, KI, GE, ME | F13: 9/12 | G13: Mayoritas (7-10/12)
... A293: 292 | B293: abc conjecture | C293: Topik | D293: 1 | E293: TE | F293: 1/12 | G293: Minoritas/Unik (1-3/12)

Sheet Ringkasan Final
A1: RINGKASAN FINAL — Analisis Komparatif 12 AI: Problem Hilbert #10 (PR#10)
A3: A. STATISTIK KESELURUHAN (semua nilai dihitung via formula dari sheet sumber)
A4: Metrik | B4: Nilai | C4: Sumber
A5: Total draft AI diproses | B5: =COUNTA('Legend Tag AI'!B2:B13) -> 12 | C5: Legend Tag AI
A6: Total baris mentah — Sheet Superset Topik-Tokoh | B6: =COUNTA('Superset Topik-Tokoh'!B2:B1000) -> 738 | C6: Superset Topik-Tokoh
A7: Total baris mentah — Sheet Konsistensi Prep vs Draft | B7: =COUNTA('Konsistensi Prep vs Draft'!D2:D1000) -> 738 | C7: Konsistensi Prep vs Draft
A8: Total kelompok kanonik (Tahap 2) | B8: =COUNTA('Konsensus 12 AI'!B2:B1000) -> 292 | C8: Konsensus 12 AI
A9: — Tokoh kanonik | B9: =COUNTIF('Konsensus 12 AI'!C2:C1000,"Tokoh") -> 194 | C9: Konsensus 12 AI
A10: — Topik kanonik | B10: =COUNTIF('Konsensus 12 AI'!C2:C1000,"Topik") -> 98 | C10: Konsensus 12 AI
A11: Rasio pemadatan (baris mentah → kelompok kanonik) | B11: =TEXT(1-(B8/B6),"0.0%") -> 60.4% | C11: dihitung (1 - B8/B6)
A12: Rata-rata Jumlah AI per kelompok kanonik | B12: =ROUND(AVERAGE('Konsensus 12 AI'!D2:D1000),2) -> 2.46 | C12: Konsensus 12 AI, kolom D
A13: Rata-rata Match Rate lintas 12 AI (%) *lihat catatan bawah | B13: =ROUND(AVERAGE('Ringkasan per AI'!E2:E13),1) -> 78.5 | C13: Ringkasan per AI, kolom E
A14: * Match Rate per AI = Match / (Match + Prep only); Draft only sengaja tak masuk penyebut (lihat Tahap 1). Metrik ini BEDA dari 'rata-rata Jumlah AI per kelompok kanonik' di atas — jangan dikonflasi meski labelnya mirip.
A16: B. RINGKASAN PER KATEGORI KONSENSUS
A17: Kategori | B17: Rentang Jumlah AI | C17: Jml Tokoh | D17: Jml Topik | E17: Jml Total | F17: % dari Total Kanonik | G17: Insight Analitis
A18: Universal | B18: 11–12/12 | C18: =COUNTIFS('Konsensus 12 AI'!$C$2:$C$1000,"Tokoh",'Konsensus 12 AI'!$D$2:$D$1000,">="&11,'Konsensus 12 AI'!$D$2:$D$1000,"<="&12) -> 9 | D18: =COUNTIFS('Konsensus 12 AI'!$C$2:$C$1000,"Topik",'Konsensus 12 AI'!$D$2:$D$1000,">="&11,'Konsensus 12 AI'!$D$2:$D$1000,"<="&12) -> 4 | E18: =C18+D18 -> 13 | F18: =TEXT(E18/$B$8,"0.0%") -> 4.5% | G18: 9 Tokoh + 4 Topik = tulang punggung narasi HTP yang disepakati nyaris semua AI: pengusul (Hilbert), objek (persamaan Diophantine & Program Hilbert/Formalisme), dan 4 tokoh penuntas 1961-1970 (Davis, Putnam, Robinson, Matiyasevich) plus Turing. Bahkan Church/Gödel 'hanya' 11/12 -- satu AI (LE) konsisten tak menyinggung salah satunya scr eksplisit.
A19: Mayoritas | B19: 7–10/12 | C19: =COUNTIFS('Konsensus 12 AI'!$C$2:$C$1000,"Tokoh",'Konsensus 12 AI'!$D$2:$D$1000,">="&7,'Konsensus 12 AI'!$D$2:$D$1000,"<="&10) -> 8 | D19: =COUNTIFS('Konsensus 12 AI'!$C$2:$C$1000,"Topik",'Konsensus 12 AI'!$D$2:$D$1000,">="&7,'Konsensus 12 AI'!$D$2:$D$1000,"<="&10) -> 9 | E19: =C19+D19 -> 17 | F19: =TEXT(E19/$B$8,"0.0%") -> 5.8% | G19: Di sinilah terobosan 2024-2026 (Koymans-Pagano, tim Poonen/Bhargava/Alpöge/Shnidman) muncul sbg 'hampir-konsensus' (9-10/12) -- menunjukkan liputan riset terkini ini sudah cukup matang utk dianggap 'pengetahuan umum' lintas-AI, bukan temuan niche. Pengecualian mencolok: LE (tak sentuh sama sekali) dan kadang QW/GE (detail tim lebih tipis).
A20: Umum | B20: 4–6/12 | C20: =COUNTIFS('Konsensus 12 AI'!$C$2:$C$1000,"Tokoh",'Konsensus 12 AI'!$D$2:$D$1000,">="&4,'Konsensus 12 AI'!$D$2:$D$1000,"<="&6) -> 9 | D20: =COUNTIFS('Konsensus 12 AI'!$C$2:$C$1000,"Topik",'Konsensus 12 AI'!$D$2:$D$1000,">="&4,'Konsensus 12 AI'!$D$2:$D$1000,"<="&6) -> 10 | E20: =C20+D20 -> 19 | F20: =TEXT(E20/$B$8,"0.0%") -> 6.5% | G20: Campuran topik teknis sekunder (Halting Problem, Persamaan Pell, Tesis Church-Turing) dan tokoh pendukung generalisasi ring (Denef, Shlapentokh, Ackermann). Menandakan bagian narasi yang 'diketahui tp opsional' -- AI yang lebih ringkas/naratif (CO, GE, QW) cenderung melewatkannya.
A21: Minoritas/Unik | B21: 1–3/12 | C21: =COUNTIFS('Konsensus 12 AI'!$C$2:$C$1000,"Tokoh",'Konsensus 12 AI'!$D$2:$D$1000,">="&1,'Konsensus 12 AI'!$D$2:$D$1000,"<="&3) -> 168 | D21: =COUNTIFS('Konsensus 12 AI'!$C$2:$C$1000,"Topik",'Konsensus 12 AI'!$D$2:$D$1000,">="&1,'Konsensus 12 AI'!$D$2:$D$1000,"<="&3) -> 75 | E21: =C21+D21 -> 243 | F21: =TEXT(E21/$B$8,"0.0%") -> 83.2% | G21: 83% dari seluruh kelompok kanonik. Didominasi Daftar Pustaka tangensial 1-AI (populer/filsafat di KI, TE, LE) dan detail super-spesifik (nama co-author ke-4/ke-5 dlm tim riset, sub-cabang teori bilangan versi KI). Di sinilah 'kepribadian' tiap AI paling kentara -- lihat Bagian E.
A22: TOTAL (cek silang) | B22: 1–12/12 | C22: =SUM(C18:C21) -> 194 | D22: =SUM(D18:D21) -> 98 | E22: =SUM(E18:E21) -> 292 | F22: =TEXT(E22/$B$8,"0.0%") -> 100.0% | G22: Baris cek: kolom Nilai/Jml Total di sini HARUS = Total kelompok kanonik (baris A8) dan % HARUS = 100.0% -- kalau tidak, ada kelompok kanonik yang salah kategori atau tercecer.
A24: C. SOROTAN KONKRET
A25: C1. UNIVERSAL (11-12/12 AI) — disepakati / nyaris disepakati SEMUA AI
A26: Jenis | B26: Item | C26: Jml AI | D26: AI yang TIDAK menyebutnya
A27: Tokoh | B27: Alan Turing | C27: 12 | D27: (semua 12 AI)
A28: Tokoh | B28: David Hilbert | C28: 12 | D28: (semua 12 AI)
A29: Tokoh | B29: Diophantus | C29: 12 | D29: (semua 12 AI)
A30: Tokoh | B30: Hilary Putnam | C30: 12 | D30: (semua 12 AI)
A31: Tokoh | B31: Julia Robinson | C31: 12 | D31: (semua 12 AI)
A32: Tokoh | B32: Martin Davis | C32: 12 | D32: (semua 12 AI)
A33: Tokoh | B33: Yuri Matiyasevich | C33: 12 | D33: (semua 12 AI)
A34: Topik | B34: Persamaan Diophantine | C34: 12 | D34: (semua 12 AI)
A35: Topik | B35: Program Hilbert & Formalisme (Aksiomatisasi, 1900) | C35: 12 | D35: (semua 12 AI)
A36: Tokoh | B36: Alonzo Church | C36: 11 | D36: CO
A37: Tokoh | B37: Kurt Gödel | C37: 11 | D37: CO
A38: Topik | B38: HTP atas Bilangan Rasional Q (masih terbuka) | C38: 11 | D38: LE
A39: Topik | B39: Teori Komputabilitas & Mesin Turing (Church-Turing, 1936) | C39: 11 | D39: GE
A41: C2. MAYORITAS (7-10/12 AI) — konsensus kuat, belum bulat
A42: Jenis | B42: Item | C42: Jml AI | D42: AI yang TIDAK menyebutnya
A43: Topik | B43: Teorema Ketidaklengkapan Gödel (1931) | C43: 10 | D43: CO, PE
A44: Topik | B44: Teorema MRDP (bukti final 1970) | C44: 10 | D44: DE, TE
...
